<?xml version="1.0" encoding="utf-8"?><testsuites><testsuite name="pytest" errors="1" failures="0" skipped="0" tests="1" time="9.820" timestamp="2024-05-12T13:13:30.923364" hostname="Mvk"><testcase classname="pytest" name="internal" time="0.000"><error message="internal error">Traceback (most recent call last):
  File "C:\Users\vinsm\AppData\Local\Programs\Python\Python310\lib\site-packages\_pytest\main.py", line 268, in wrap_session
    session.exitstatus = doit(config, session) or 0
  File "C:\Users\vinsm\AppData\Local\Programs\Python\Python310\lib\site-packages\_pytest\main.py", line 322, in _main
    config.hook.pytest_runtestloop(session=session)
  File "C:\Users\vinsm\AppData\Local\Programs\Python\Python310\lib\site-packages\pluggy\_hooks.py", line 265, in __call__
    return self._hookexec(self.name, self.get_hookimpls(), kwargs, firstresult)
  File "C:\Users\vinsm\AppData\Local\Programs\Python\Python310\lib\site-packages\pluggy\_manager.py", line 80, in _hookexec
    return self._inner_hookexec(hook_name, methods, kwargs, firstresult)
  File "C:\Users\vinsm\AppData\Local\Programs\Python\Python310\lib\site-packages\pluggy\_callers.py", line 60, in _multicall
    return outcome.get_result()
  File "C:\Users\vinsm\AppData\Local\Programs\Python\Python310\lib\site-packages\pluggy\_result.py", line 60, in get_result
    raise ex[1].with_traceback(ex[2])
  File "C:\Users\vinsm\AppData\Local\Programs\Python\Python310\lib\site-packages\pluggy\_callers.py", line 39, in _multicall
    res = hook_impl.function(*args)
  File "C:\Users\vinsm\AppData\Local\Programs\Python\Python310\lib\site-packages\_pytest\main.py", line 347, in pytest_runtestloop
    item.config.hook.pytest_runtest_protocol(item=item, nextitem=nextitem)
  File "C:\Users\vinsm\AppData\Local\Programs\Python\Python310\lib\site-packages\pluggy\_hooks.py", line 265, in __call__
    return self._hookexec(self.name, self.get_hookimpls(), kwargs, firstresult)
  File "C:\Users\vinsm\AppData\Local\Programs\Python\Python310\lib\site-packages\pluggy\_manager.py", line 80, in _hookexec
    return self._inner_hookexec(hook_name, methods, kwargs, firstresult)
  File "C:\Users\vinsm\AppData\Local\Programs\Python\Python310\lib\site-packages\pluggy\_callers.py", line 60, in _multicall
    return outcome.get_result()
  File "C:\Users\vinsm\AppData\Local\Programs\Python\Python310\lib\site-packages\pluggy\_result.py", line 60, in get_result
    raise ex[1].with_traceback(ex[2])
  File "C:\Users\vinsm\AppData\Local\Programs\Python\Python310\lib\site-packages\pluggy\_callers.py", line 39, in _multicall
    res = hook_impl.function(*args)
  File "C:\Users\vinsm\AppData\Local\Programs\Python\Python310\lib\site-packages\_pytest\runner.py", line 113, in pytest_runtest_protocol
    runtestprotocol(item, nextitem=nextitem)
  File "C:\Users\vinsm\AppData\Local\Programs\Python\Python310\lib\site-packages\_pytest\runner.py", line 126, in runtestprotocol
    rep = call_and_report(item, "setup", log)
  File "C:\Users\vinsm\AppData\Local\Programs\Python\Python310\lib\site-packages\_pytest\runner.py", line 223, in call_and_report
    report: TestReport = hook.pytest_runtest_makereport(item=item, call=call)
  File "C:\Users\vinsm\AppData\Local\Programs\Python\Python310\lib\site-packages\pluggy\_hooks.py", line 265, in __call__
    return self._hookexec(self.name, self.get_hookimpls(), kwargs, firstresult)
  File "C:\Users\vinsm\AppData\Local\Programs\Python\Python310\lib\site-packages\pluggy\_manager.py", line 80, in _hookexec
    return self._inner_hookexec(hook_name, methods, kwargs, firstresult)
  File "C:\Users\vinsm\AppData\Local\Programs\Python\Python310\lib\site-packages\pluggy\_callers.py", line 55, in _multicall
    gen.send(outcome)
  File "C:\Users\vinsm\AppData\Local\Programs\Python\Python310\lib\site-packages\_pytest\skipping.py", line 273, in pytest_runtest_makereport
    elif not rep.skipped and xfailed:
AttributeError: 'generator' object has no attribute 'skipped'</error></testcase></testsuite></testsuites>